Workbook

Sheet A1_DDM_Walmart
B4: 1. Cost of Equity (CAPM)
B5: Risk-free rate, Rf | D5: 0.0447
B6: Beta, β | D6: 0.55
B7: Equity risk premium, ERP | D7: 0.055
B8: Cost of equity, Ke = Rf + β×ERP | D8: =D5+D6*D7 -> 0.07495
B10: 2. Dividend Growth Taper (Years 1–5)
B11: Current dividend, D0 | D11: 0.99
B12: Near-term (Year 1) growth rate | D12: 0.053
B13: Terminal growth rate (Year 5 / perpetuity), g | D13: 0.04
B15: Year | C15: Growth rate | D15: Dividend (Dt) | E15: Discount factor @Ke | F15: PV of dividend
B16: 1 | D16: =D12 -> 0.053 | E16: =D11*(1+D16) -> 1.04247 | F16: =1/(1+$D$8)^1 -> 0.93027583 | G16: =E16*F16 -> 0.96978464
B17: 2 | D17: =$D$12+(2-1)*($D$13-$D$12)/4 -> 0.04975 | E17: =E16*(1+D17) -> 1.0943329 | F17: =1/(1+$D$8)^2 -> 0.86541311 | G17: =E17*F17 -> 0.94705003
B18: 3 | D18: =$D$12+(3-1)*($D$13-$D$12)/4 -> 0.0465 | E18: =E17*(1+D18) -> 1.1452194 | F18: =1/(1+$D$8)^3 -> 0.8050729 | G18: =E18*F18 -> 0.92198507
B19: 4 | D19: =$D$12+(4-1)*($D$13-$D$12)/4 -> 0.04325 | E19: =E18*(1+D19) -> 1.1947501 | F19: =1/(1+$D$8)^4 -> 0.74893986 | G19: =E19*F19 -> 0.89479597
B20: 5 | D20: =$D$12+(5-1)*($D$13-$D$12)/4 -> 0.04 | E20: =E19*(1+D20) -> 1.2425401 | F20: =1/(1+$D$8)^5 -> 0.69672065 | G20: =E20*F20 -> 0.86570334
B21: PV of explicit dividends (Years 1–5) | G21: =SUM(G16:G20) -> 4.5993191
B23: 3. Terminal Value (Gordon Growth)
B24: Terminal value at Year 5 = D5×(1+g) / (Ke−g) | D24: =E20*(1+D13)/(D8-D13) -> 36.974012
B25: PV of terminal value = TV / (1+Ke)^5 | D25: =D24/(1+D8)^5 -> 25.760557
B27: 4. Intrinsic Value & Market Comparison
B28: Intrinsic value per share (DDM) | D28: =G21+D25 -> 30.359876
B29: Current market price | D29: 111.84
B30: Premium / (discount) of market price to intrinsic value | D30: =D29/D28-1 -> 2.6838095
B31: Classification (DDM basis) | D31: =IF(D30>0.05,"Overvalued",IF(D30<-0.05,"Undervalued","Fairly valued")) -> Overvalued

Sheet A2_DDM_Costco
B4: 1. Cost of Equity (CAPM)
B5: Risk-free rate, Rf | D5: 0.0447
B6: Beta, β | D6: 0.75
B7: Equity risk premium, ERP | D7: 0.055
B8: Cost of equity, Ke = Rf + β×ERP | D8: =D5+D6*D7 -> 0.08595
B10: 2. Dividend Growth Taper (Years 1–5)
B11: Current dividend, D0 | D11: 5.2
B12: Near-term (Year 1) growth rate | D12: 0.12
B13: Terminal growth rate (Year 5 / perpetuity), g | D13: 0.06
B15: Year | C15: Growth rate | D15: Dividend (Dt) | E15: Discount factor @Ke | F15: PV of dividend
B16: 1 | D16: =D12 -> 0.12 | E16: =D11*(1+D16) -> 5.824 | F16: =1/(1+$D$8)^1 -> 0.92085271 | G16: =E16*F16 -> 5.3630462
B17: 2 | D17: =$D$12+(2-1)*($D$13-$D$12)/4 -> 0.105 | E17: =E16*(1+D17) -> 6.43552 | F17: =1/(1+$D$8)^2 -> 0.84796971 | G17: =E17*F17 -> 5.457126
B18: 3 | D18: =$D$12+(3-1)*($D$13-$D$12)/4 -> 0.09 | E18: =E17*(1+D18) -> 7.0147168 | F18: =1/(1+$D$8)^3 -> 0.78085521 | G18: =E18*F18 -> 5.4774781
B19: 4 | D19: =$D$12+(4-1)*($D$13-$D$12)/4 -> 0.075 | E19: =E18*(1+D19) -> 7.5408206 | F19: =1/(1+$D$8)^4 -> 0.71905263 | G19: =E19*F19 -> 5.4222469
B20: 5 | D20: =$D$12+(5-1)*($D$13-$D$12)/4 -> 0.06 | E20: =E19*(1+D20) -> 7.9932698 | F20: =1/(1+$D$8)^5 -> 0.66214157 | G20: =E20*F20 -> 5.2926762
B21: PV of explicit dividends (Years 1–5) | G21: =SUM(G16:G20) -> 27.012573
B23: 3. Terminal Value (Gordon Growth)
B24: Terminal value at Year 5 = D5×(1+g) / (Ke−g) | D24: =E20*(1+D13)/(D8-D13) -> 326.50736
B25: PV of terminal value = TV / (1+Ke)^5 | D25: =D24/(1+D8)^5 -> 216.19409
B27: 4. Intrinsic Value & Market Comparison
B28: Intrinsic value per share (DDM) | D28: =G21+D25 -> 243.20667
B29: Current market price | D29: 935.47
B30: Premium / (discount) of market price to intrinsic value | D30: =D29/D28-1 -> 2.8463995
B31: Classification (DDM basis) | D31: =IF(D30>0.05,"Overvalued",IF(D30<-0.05,"Undervalued","Fairly valued")) -> Overvalued

Sheet A3_DDM_Target
B4: 1. Cost of Equity (CAPM)
B5: Risk-free rate, Rf | D5: 0.0447
B6: Beta, β | D6: 1.05
B7: Equity risk premium, ERP | D7: 0.055
B8: Cost of equity, Ke = Rf + β×ERP | D8: =D5+D6*D7 -> 0.10245
B10: 2. Dividend Growth Taper (Years 1–5)
B11: Current dividend, D0 | D11: 4.52
B12: Near-term (Year 1) growth rate | D12: 0.015
B13: Terminal growth rate (Year 5 / perpetuity), g | D13: 0.03
B15: Year | C15: Growth rate | D15: Dividend (Dt) | E15: Discount factor @Ke | F15: PV of dividend
B16: 1 | D16: =D12 -> 0.015 | E16: =D11*(1+D16) -> 4.5878 | F16: =1/(1+$D$8)^1 -> 0.90707062 | G16: =E16*F16 -> 4.1614586
B17: 2 | D17: =$D$12+(2-1)*($D$13-$D$12)/4 -> 0.01875 | E17: =E16*(1+D17) -> 4.6738212 | F17: =1/(1+$D$8)^2 -> 0.8227771 | G17: =E17*F17 -> 3.8455131
B18: 3 | D18: =$D$12+(3-1)*($D$13-$D$12)/4 -> 0.0225 | E18: =E17*(1+D18) -> 4.7789822 | F18: =1/(1+$D$8)^3 -> 0.74631693 | G18: =E18*F18 -> 3.5666354
B19: 4 | D19: =$D$12+(4-1)*($D$13-$D$12)/4 -> 0.02625 | E19: =E18*(1+D19) -> 4.9044305 | F19: =1/(1+$D$8)^4 -> 0.67696216 | G19: =E19*F19 -> 3.3201139
B20: 5 | D20: =$D$12+(5-1)*($D$13-$D$12)/4 -> 0.03 | E20: =E19*(1+D20) -> 5.0515634 | F20: =1/(1+$D$8)^5 -> 0.61405248 | G20: =E20*F20 -> 3.1019251
B21: PV of explicit dividends (Years 1–5) | G21: =SUM(G16:G20) -> 17.995646
B23: 3. Terminal Value (Gordon Growth)
B24: Terminal value at Year 5 = D5×(1+g) / (Ke−g) | D24: =E20*(1+D13)/(D8-D13) -> 71.816568
B25: PV of terminal value = TV / (1+Ke)^5 | D25: =D24/(1+D8)^5 -> 44.099142
B27: 4. Intrinsic Value & Market Comparison
B28: Intrinsic value per share (DDM) | D28: =G21+D25 -> 62.094788
B29: Current market price | D29: 130.56
B30: Premium / (discount) of market price to intrinsic value | D30: =D29/D28-1 -> 1.1025919
B31: Classification (DDM basis) | D31: =IF(D30>0.05,"Overvalued",IF(D30<-0.05,"Undervalued","Fairly valued")) -> Overvalued

Sheet A4_Relative_Valuation
B5: Company | C5: Ticker | D5: Price (USD) | E5: Trailing P/E | F5: EV/EBITDA
B6: Walmart | C6: WMT | D6: 111.84 | E6: 38.32 | F6: 19.31
B7: Target | C7: TGT | D7: 130.56 | E7: 17.25 | F7: 9.28
B8: Costco | C8: COST | D8: 935.47 | E8: 47.06 | F8: 30.1
B9: Dollar General | C9: DG | D9: 116.42 | E9: 17.8 | F9: 10.2
B10: Dollar Tree | C10: DLTR | D10: 123.4 | E10: 19.4 | F10: 9.85
B11: Peer group average | E11: =AVERAGE(E6:E10) -> 27.966 | F11: =AVERAGE(F6:F10) -> 15.748
B13: Absolute vs Relative vs Market Summary
B14: Company | C14: DDM value | D14: Market price | E14: P/E vs peer avg | F14: EV/EBITDA vs peer avg | G14: Relative view
B15: Walmart | C15: =A1_DDM_Walmart!D28 -> 30.359876 | D15: =A1_DDM_Walmart!D29 -> 111.84 | E15: =E6/$E$11-1 -> 0.37023529 | F15: =F6/$F$11-1 -> 0.22618745 | G15: =IF(E15>0,"Premium to peers","Discount to peers") -> Premium to peers
B16: Target | C16: =A3_DDM_Target!D28 -> 62.094788 | D16: =A3_DDM_Target!D29 -> 130.56 | E16: =E7/$E$11-1 -> -0.38317958 | F16: =F7/$F$11-1 -> -0.41071882 | G16: =IF(E16>0,"Premium to peers","Discount to peers") -> Discount to peers
B17: Costco | C17: =A2_DDM_Costco!D28 -> 243.20667 | D17: =A2_DDM_Costco!D29 -> 935.47 | E17: =E8/$E$11-1 -> 0.68275763 | F17: =F8/$F$11-1 -> 0.91135382 | G17: =IF(E17>0,"Premium to peers","Discount to peers") -> Premium to peers

Sheet B_Bond_Analysis
B4: 1. Bond Characteristics & Price Verification
B5: Bond | C5: Face value | D5: Coupon rate | E5: Annual coupon | F5: Years to maturity | G5: Yield | H5: Given price | I5: DCF price (check)
B6: Bond A | C6: 100 | D6: 0.15 | E6: =C6*D6 -> 15 | F6: 5 | G6: 0.1 | H6: 118.95 | I6: =E6*(1-(1+G6)^-F6)/G6+C6*(1+G6)^-F6 -> 118.95393
B7: Bond B | C7: 100 | D7: 0.15 | E7: =C7*D7 -> 15 | F7: 10 | G7: =G6 -> 0.1 | H7: 130.72 | I7: =E7*(1-(1+G7)^-F7)/G7+C7*(1+G7)^-F7 -> 130.72284
B9: 2. Cash Flow Schedules & Duration/Convexity (Bond A, n=5 and Bond B, n=10)
B10: Bond A (5-year) cash flow schedule
B11: t | C11: Cash flow (CFt) | D11: Discount factor | E11: PV(CFt) | F11: t × PV(CFt) | G11: t(t+1) × PV(CFt)
B12: 1 | C12: =15 -> 15 | D12: =1/(1+0.1)^1 -> 0.90909091 | E12: =C12*D12 -> 13.636364 | F12: =1*E12 -> 13.636364 | G12: =1*(1+1)*E12 -> 27.272727
B13: 2 | C13: =15 -> 15 | D13: =1/(1+0.1)^2 -> 0.82644628 | E13: =C13*D13 -> 12.396694 | F13: =2*E13 -> 24.793388 | G13: =2*(2+1)*E13 -> 74.380165
B14: 3 | C14: =15 -> 15 | D14: =1/(1+0.1)^3 -> 0.7513148 | E14: =C14*D14 -> 11.269722 | F14: =3*E14 -> 33.809166 | G14: =3*(3+1)*E14 -> 135.23666
B15: 4 | C15: =15 -> 15 | D15: =1/(1+0.1)^4 -> 0.68301346 | E15: =C15*D15 -> 10.245202 | F15: =4*E15 -> 40.980807 | G15: =4*(4+1)*E15 -> 204.90404
B16: 5 | C16: =15+100 -> 115 | D16: =1/(1+0.1)^5 -> 0.62092132 | E16: =C16*D16 -> 71.405952 | F16: =5*E16 -> 357.02976 | G16: =5*(5+1)*E16 -> 2142.1786
B17: Sum PV(CFt) [= price] | E17: =SUM(E12:E16) -> 118.95393
B18: Sum t×PV(CFt) | F18: =SUM(F12:F16) -> 470.24949
B19: Sum t(t+1)×PV(CFt) | G19: =SUM(G12:G16) -> 2583.9722
B21: Macaulay Duration = Σ[t×PV(CFt)] / Price | D21: =F18/E17 -> 3.9532067
B22: Modified Duration = Macaulay / (1+y) | D22: =D21/(1+0.1) -> 3.5938243
B23: Convexity = Σ[t(t+1)×PV(CFt)] / [Price×(1+y)²] | D23: =G19/(E17*(1+0.1)^2) -> 17.952447
B26: Bond B (10-year) cash flow schedule
B27: t | C27: Cash flow (CFt) | D27: Discount factor | E27: PV(CFt) | F27: t × PV(CFt) | G27: t(t+1) × PV(CFt)
B28: 1 | C28: =15 -> 15 | D28: =1/(1+0.1)^1 -> 0.90909091 | E28: =C28*D28 -> 13.636364 | F28: =1*E28 -> 13.636364 | G28: =1*(1+1)*E28 -> 27.272727
B29: 2 | C29: =15 -> 15 | D29: =1/(1+0.1)^2 -> 0.82644628 | E29: =C29*D29 -> 12.396694 | F29: =2*E29 -> 24.793388 | G29: =2*(2+1)*E29 -> 74.380165
B30: 3 | C30: =15 -> 15 | D30: =1/(1+0.1)^3 -> 0.7513148 | E30: =C30*D30 -> 11.269722 | F30: =3*E30 -> 33.809166 | G30: =3*(3+1)*E30 -> 135.23666
B31: 4 | C31: =15 -> 15 | D31: =1/(1+0.1)^4 -> 0.68301346 | E31: =C31*D31 -> 10.245202 | F31: =4*E31 -> 40.980807 | G31: =4*(4+1)*E31 -> 204.90404
B32: 5 | C32: =15 -> 15 | D32: =1/(1+0.1)^5 -> 0.62092132 | E32: =C32*D32 -> 9.3138198 | F32: =5*E32 -> 46.569099 | G32: =5*(5+1)*E32 -> 279.4146
B33: 6 | C33: =15 -> 15 | D33: =1/(1+0.1)^6 -> 0.56447393 | E33: =C33*D33 -> 8.467109 | F33: =6*E33 -> 50.802654 | G33: =6*(6+1)*E33 -> 355.61858
B34: 7 | C34: =15 -> 15 | D34: =1/(1+0.1)^7 -> 0.51315812 | E34: =C34*D34 -> 7.6973718 | F34: =7*E34 -> 53.881602 | G34: =7*(7+1)*E34 -> 431.05282
B35: 8 | C35: =15 -> 15 | D35: =1/(1+0.1)^8 -> 0.46650738 | E35: =C35*D35 -> 6.9976107 | F35: =8*E35 -> 55.980886 | G35: =8*(8+1)*E35 -> 503.82797
B36: 9 | C36: =15 -> 15 | D36: =1/(1+0.1)^9 -> 0.42409762 | E36: =C36*D36 -> 6.3614643 | F36: =9*E36 -> 57.253178 | G36: =9*(9+1)*E36 -> 572.53178
B37: 10 | C37: =15+100 -> 115 | D37: =1/(1+0.1)^10 -> 0.38554329 | E37: =C37*D37 -> 44.337478 | F37: =10*E37 -> 443.37478 | G37: =10*(10+1)*E37 -> 4877.1226
B38: Sum PV(CFt) [= price] | E38: =SUM(E28:E37) -> 130.72284
B39: Sum t×PV(CFt) | F39: =SUM(F28:F37) -> 821.08193
B40: Sum t(t+1)×PV(CFt) | G40: =SUM(G28:G37) -> 7461.362
B42: Macaulay Duration = Σ[t×PV(CFt)] / Price | D42: =F39/E38 -> 6.2810903
B43: Modified Duration = Macaulay / (1+y) | D43: =D42/(1+0.1) -> 5.710082
B44: Convexity = Σ[t(t+1)×PV(CFt)] / [Price×(1+y)²] | D44: =G40/(E38*(1+0.1)^2) -> 47.171673
B46: 3. Duration & Convexity Summary
B47: Bond | C47: Macaulay Duration (yrs) | D47: Modified Duration | E47: Convexity
B48: Bond A (5-year) | C48: =D21 -> 3.9532067 | D48: =D22 -> 3.5938243 | E48: =D23 -> 17.952447
B49: Bond B (10-year) | C49: =D42 -> 6.2810903 | D49: =D43 -> 5.710082 | E49: =D44 -> 47.171673
...

Sheet D_BSM_Straddle
B5: 1. Inputs
B6: Spot price, S0 | D6: 326.54
B7: Strike price, K | D7: 327
B8: Time to maturity (days) | D8: 14
B9: Time to maturity, T (years) = days/365 | D9: =D8/365 -> 0.038356164
B10: Risk-free rate, r | D10: 0.001
B11: Implied volatility, σ | D11: 0.38
B13: 2. Black-Scholes-Merton Calculation
B14: d1 = [ln(S0/K) + (r+σ²/2)×T] / (σ×√T) | D14: =(LN(D6/D7)+(D10+D11^2/2)*D9)/(D11*SQRT(D9)) -> 0.018811017
B15: d2 = d1 − σ×√T | D15: =D14-D11*SQRT(D9) -> -0.055610956
B16: N(d1) | D16: =NORMSDIST(D14) -> 0.50750407
B17: N(d2) | D17: =NORMSDIST(D15) -> 0.47782587
B18: N(-d1) | D18: =NORMSDIST(-D14) -> 0.49249593
B19: N(-d2) | D19: =NORMSDIST(-D15) -> 0.52217413
B21: Call price, C = S0×N(d1) − K×e^(−rT)×N(d2) | D21: =D6*D16-D7*EXP(-D10*D9)*D17 -> 9.4773124
B22: Put price, P = K×e^(−rT)×N(−d2) − S0×N(−d1) | D22: =D7*EXP(-D10*D9)*D19-D6*D18 -> 9.9247701
B23: Straddle cost = Call + Put | D23: =D21+D22 -> 19.402082
B25: 3. Breakeven Points
B26: Lower breakeven = K − Premium | D26: =D7-D23 -> 307.59792
B27: Upper breakeven = K + Premium | D27: =D7+D23 -> 346.40208
B29: 4. Profit & Loss at Maturity (realised outcome)
B30: SPY at expiry, St | D30: 355.33
B31: Call payoff = MAX(St−K, 0) | D31: =MAX(D30-D7,0) -> 28.33
B32: Put payoff = MAX(K−St, 0) | D32: =MAX(D7-D30,0) -> 0
B33: Total straddle payoff | D33: =D31+D32 -> 28.33
B34: Straddle premium paid | D34: =D23 -> 19.402082
B35: Net P&L per straddle | D35: =D33-D34 -> 8.9279175
B36: Return on premium | D36: =D35/D34 -> 0.46015254
B38: 5. Payoff Diagram Data (for chart)
B39: SPY price at expiry | C39: Call payoff | D39: Put payoff | E39: Gross payoff | F39: Net P&L (less premium)
B40: 260 | C40: =MAX(B40-$D$7,0) -> 0 | D40: =MAX($D$7-B40,0) -> 67 | E40: =C40+D40 -> 67 | F40: =E40-$D$23 -> 47.597918
B41: 270 | C41: =MAX(B41-$D$7,0) -> 0 | D41: =MAX($D$7-B41,0) -> 57 | E41: =C41+D41 -> 57 | F41: =E41-$D$23 -> 37.597918
B42: 280 | C42: =MAX(B42-$D$7,0) -> 0 | D42: =MAX($D$7-B42,0) -> 47 | E42: =C42+D42 -> 47 | F42: =E42-$D$23 -> 27.597918
B43: 290 | C43: =MAX(B43-$D$7,0) -> 0 | D43: =MAX($D$7-B43,0) -> 37 | E43: =C43+D43 -> 37 | F43: =E43-$D$23 -> 17.597918
B44: 300 | C44: =MAX(B44-$D$7,0) -> 0 | D44: =MAX($D$7-B44,0) -> 27 | E44: =C44+D44 -> 27 | F44: =E44-$D$23 -> 7.5979175
B45: 310 | C45: =MAX(B45-$D$7,0) -> 0 | D45: =MAX($D$7-B45,0) -> 17 | E45: =C45+D45 -> 17 | F45: =E45-$D$23 -> -2.4020825
B46: 320 | C46: =MAX(B46-$D$7,0) -> 0 | D46: =MAX($D$7-B46,0) -> 7 | E46: =C46+D46 -> 7 | F46: =E46-$D$23 -> -12.402082
B47: 330 | C47: =MAX(B47-$D$7,0) -> 3 | D47: =MAX($D$7-B47,0) -> 0 | E47: =C47+D47 -> 3 | F47: =E47-$D$23 -> -16.402082
B48: 340 | C48: =MAX(B48-$D$7,0) -> 13 | D48: =MAX($D$7-B48,0) -> 0 | E48: =C48+D48 -> 13 | F48: =E48-$D$23 -> -6.4020825
B49: 350 | C49: =MAX(B49-$D$7,0) -> 23 | D49: =MAX($D$7-B49,0) -> 0 | E49: =C49+D49 -> 23 | F49: =E49-$D$23 -> 3.5979175
...
